{"uuid": "dd2a2c6b-92cb-4dec-819f-e854e182efcd", "children": ["f7a2542c-af36-4381-bdd2-c53fe10ae8b6"], "befores": [{"name": "browser", "status": "passed", "start": 1574176144706, "stop": 1574176166963}], "afters": [{"name": "browser::0", "status": "broken", "statusDetails": {"message": "selenium.common.exceptions.WebDriverException: Message: chrome not reachable\n  (Session info: chrome=78.0.3904.97)\n\n", "trace": "  File \"c:\\users\\patelvi\\appdata\\local\\programs\\python\\python37-32\\lib\\site-packages\\allure_commons\\_allure.py\", line 185, in __call__\n    return self._fixture_function(*args, **kwargs)\n  File \"c:\\users\\patelvi\\appdata\\local\\programs\\python\\python37-32\\lib\\site-packages\\_pytest\\fixtures.py\", line 787, in _teardown_yield_fixture\n    next(it)\n  File \"C:\\Users\\patelvi\\PycharmProjects\\NCE\\onx\\test_multi.py\", line 60, in browser\n    driver.close()\n  File \"c:\\users\\patelvi\\appdata\\local\\programs\\python\\python37-32\\lib\\site-packages\\selenium\\webdriver\\remote\\webdriver.py\", line 688, in close\n    self.execute(Command.CLOSE)\n  File \"c:\\users\\patelvi\\appdata\\local\\programs\\python\\python37-32\\lib\\site-packages\\selenium\\webdriver\\remote\\webdriver.py\", line 321, in execute\n    self.error_handler.check_response(response)\n  File \"c:\\users\\patelvi\\appdata\\local\\programs\\python\\python37-32\\lib\\site-packages\\selenium\\webdriver\\remote\\errorhandler.py\", line 242, in check_response\n    raise exception_class(message, screen, stacktrace)\n"}, "start": 1574176175945, "stop": 1574176177956}], "start": 1574176144706, "stop": 1574176177957}