{"uuid": "1248fded-f4fb-463e-9243-196d52220557", "children": ["2ece3fe5-4381-4bd4-895d-6310a65dae58"], "befores": [{"name": "browser", "status": "passed", "start": 1574175240199, "stop": 1574175249015}], "afters": [{"name": "browser::0", "status": "broken", "statusDetails": {"message": "selenium.common.exceptions.InvalidSessionIdException: Message: Tried to run command without establishing a connection\n\n", "trace": "  File \"c:\\users\\patelvi\\appdata\\local\\programs\\python\\python37-32\\lib\\site-packages\\allure_commons\\_allure.py\", line 185, in __call__\n    return self._fixture_function(*args, **kwargs)\n  File \"c:\\users\\patelvi\\appdata\\local\\programs\\python\\python37-32\\lib\\site-packages\\_pytest\\fixtures.py\", line 787, in _teardown_yield_fixture\n    next(it)\n  File \"C:\\Users\\patelvi\\PycharmProjects\\NCE\\onx\\test_multi.py\", line 65, in browser\n    driver.close()\n  File \"c:\\users\\patelvi\\appdata\\local\\programs\\python\\python37-32\\lib\\site-packages\\selenium\\webdriver\\remote\\webdriver.py\", line 688, in close\n    self.execute(Command.CLOSE)\n  File \"c:\\users\\patelvi\\appdata\\local\\programs\\python\\python37-32\\lib\\site-packages\\selenium\\webdriver\\remote\\webdriver.py\", line 321, in execute\n    self.error_handler.check_response(response)\n  File \"c:\\users\\patelvi\\appdata\\local\\programs\\python\\python37-32\\lib\\site-packages\\selenium\\webdriver\\remote\\errorhandler.py\", line 242, in check_response\n    raise exception_class(message, screen, stacktrace)\n"}, "start": 1574175254896, "stop": 1574175254942}], "start": 1574175240199, "stop": 1574175254942}